<?xml version="1.0" ?>
  <robot name="myrobot">

  <link name="world"/>
  <link name="base"/>
  <link name="shoulder"/>
  <link name="elbow"/>
  <link name="gripper"/>

  <joint name="base_joint" type="continuous">
    <origin xyz="0.0 0.0 0.1" rpy="0 0.0 0.0"/>
    <parent link="world"/>
    <child link="base"/>
    <axis xyz="0.0 0.0 1.0"/>
  </joint>

  <joint name="shoulder_joint" type="revolute">
    <origin xyz="0.0 0.0 0.5" rpy="1.57 0.0 0.0"/>
    <parent link="base"/>
    <child link="shoulder"/>
    <axis xyz="0.0 0.0 1.0"/>
    <limit lower="-1.57" upper="1.57" effort="10.0" velocity="1.0"/>
  </joint>

  <joint name="elbow_joint" type="revolute">
    <origin xyz="0.5 0.0 0.0" rpy="0.0 0.0 0.0"/>
    <parent link="shoulder"/>
    <child link="elbow"/>
    <axis xyz="0.0 0.0 1.0"/>
    <limit lower="-1.57" upper="1.57" effort="8.0" velocity="1.0"/>
  </joint>

  <joint name="gripper_joint" type="prismatic">
    <origin xyz="0.5 0.0 0.0" rpy="1.57 0.0 1.57"/>
    <parent link="elbow"/>
    <child link="gripper"/>
    <axis xyz="0.0 0.0 1.0"/>
    <limit lower="0.0" upper="0.1" effort="2.0" velocity="0.05"/>
  </joint>

</robot>